Workbook

Sheet moje
A1: id | B1: continent | C1: region | D1: area | E1: terrain | F1: religion | G1: climate | H1: culture | I1: goods | J1: name | K1: colonization difficulty | L1: manpower | M1: tax | N1: org_id | O1: FTG Name | P1: TILES
A2: 1 | B2: America | C2: North America | D2: Alaska | E2: mountain | F2: pagan | G2: arctic | H2: inuit | I2: gold | J2: Yukon | K2: 9 | L2: 1 | M2: 1 | N2: 1 | O2: =_xlfn.XLOOKUP(Table4[[#This Row],[id]],VALINA[id],VALINA[name]) -> Yukon | P2: =_xlfn.XLOOKUP(Table4[[#This Row],[id]],prov_color!A:A,prov_color!C:C) -> 65
A3: 2 | B3: America | C3: North America | D3: Alaska | E3: mountain | F3: pagan | G3: arctic | H3: inuit | I3: fur | J3: Kitimat | K3: 8 | L3: 1 | M3: 1 | N3: 2 | O3: =_xlfn.XLOOKUP(Table4[[#This Row],[id]],VALINA[id],VALINA[name]) -> Kitimat | P3: =_xlfn.XLOOKUP(Table4[[#This Row],[id]],prov_color!A:A,prov_color!C:C) -> 23
A4: 3 | B4: America | C4: North America | D4: Alaska | E4: forest | F4: pagan | G4: arctic | H4: salishan | I4: fur | J4: Sitka | K4: 7 | L4: 1 | M4: 1 | N4: 3 | O4: =_xlfn.XLOOKUP(Table4[[#This Row],[id]],VALINA[id],VALINA[name]) -> Sitka | P4: =_xlfn.XLOOKUP(Table4[[#This Row],[id]],prov_color!A:A,prov_color!C:C) -> 76
A5: 4 | B5: America | C5: North America | D5: Oregon | E5: mountain | F5: pagan | G5: ncontinental | H5: salishan | I5: fish | J5: Nanaimo | K5: 7 | L5: 1 | M5: 2 | N5: 4 | O5: =_xlfn.XLOOKUP(Table4[[#This Row],[id]],VALINA[id],VALINA[name]) -> Nanaimo | P5: =_xlfn.XLOOKUP(Table4[[#This Row],[id]],prov_color!A:A,prov_color!C:C) -> 52
A6: 5 | B6: America | C6: North America | D6: Oregon | E6: mountain | F6: pagan | G6: ncontinental | H6: salishan | I6: naval supplies | J6: Olympia | K6: 6 | L6: 1 | M6: 3 | N6: 5 | O6: =_xlfn.XLOOKUP(Table4[[#This Row],[id]],VALINA[id],VALINA[name]) -> Olympia | P6: =_xlfn.XLOOKUP(Table4[[#This Row],[id]],prov_color!A:A,prov_color!C:C) -> 81
A7: 6 | B7: America | C7: North America | D7: Oregon | E7: forest | F7: pagan | G7: ncontinental | H7: salishan | I7: fur | J7: Columbia | K7: 4 | L7: 1 | M7: 5 | N7: 6 | O7: =_xlfn.XLOOKUP(Table4[[#This Row],[id]],VALINA[id],VALINA[name]) -> Columbia | P7: =_xlfn.XLOOKUP(Table4[[#This Row],[id]],prov_color!A:A,prov_color!C:C) -> 54
A8: 7 | B8: America | C8: North America | D8: Oregon | E8: forest | F8: pagan | G8: ncontinental | H8: salishan | I8: fur | J8: Nehalem | K8: 5 | L8: 1 | M8: 3 | N8: 7 | O8: =_xlfn.XLOOKUP(Table4[[#This Row],[id]],VALINA[id],VALINA[name]) -> Nehalem | P8: =_xlfn.XLOOKUP(Table4[[#This Row],[id]],prov_color!A:A,prov_color!C:C) -> 45
A9: 8 | B9: America | C9: North America | D9: California | E9: plains | F9: pagan | G9: temperate | H9: miwok | I9: wine | J9: Sacramento | K9: 2 | L9: 2 | M9: 7 | N9: 8 | O9: =_xlfn.XLOOKUP(Table4[[#This Row],[id]],VALINA[id],VALINA[name]) -> Sacramento | P9: =_xlfn.XLOOKUP(Table4[[#This Row],[id]],prov_color!A:A,prov_color!C:C) -> 45
A10: 9 | B10: America | C10: North America | D10: California | E10: mountain | F10: pagan | G10: temperate | H10: miwok | I10: gold | J10: Monterey | K10: 4 | L10: 1 | M10: 5 | N10: 9 | O10: =_xlfn.XLOOKUP(Table4[[#This Row],[id]],VALINA[id],VALINA[name]) -> Monterey | P10: =_xlfn.XLOOKUP(Table4[[#This Row],[id]],prov_color!A:A,prov_color!C:C) -> 37
A11: 10 | B11: America | C11: North America | D11: California | E11: mountain | F11: pagan | G11: temperate | H11: takic | I11: wool | J11: Sierra Madre | K11: 4 | L11: 1 | M11: 4 | N11: 10 | O11: =_xlfn.XLOOKUP(Table4[[#This Row],[id]],VALINA[id],VALINA[name]) -> Sierra Madre | P11: =_xlfn.XLOOKUP(Table4[[#This Row],[id]],prov_color!A:A,prov_color!C:C) -> 40
A12: 11 | B12: America | C12: North America | D12: California | E12: plains | F12: pagan | G12: temperate | H12: takic | I12: grain | J12: San Bernardino | K12: 3 | L12: 2 | M12: 5 | N12: 11 | O12: =_xlfn.XLOOKUP(Table4[[#This Row],[id]],VALINA[id],VALINA[name]) -> San Bernardino | P12: =_xlfn.XLOOKUP(Table4[[#This Row],[id]],prov_color!A:A,prov_color!C:C) -> 53
A13: 12 | B13: America | C13: Central America | D13: Sonora | E13: mountain | F13: pagan | G13: desertic | H13: hokan | I13: fish | J13: Ensenada | K13: 8 | L13: 1 | M13: 1 | N13: 12 | O13: =_xlfn.XLOOKUP(Table4[[#This Row],[id]],VALINA[id],VALINA[name]) -> Ensenada | P13: =_xlfn.XLOOKUP(Table4[[#This Row],[id]],prov_color!A:A,prov_color!C:C) -> 38
... A825: 824 | B825: Africa | C825: West Africa | D825: St Helena | E825: mountain | F825: pagan | G825: temperate | H825: tehuelche | I825: fish | J825: St. Helena | K825: 3 | L825: 1 | M825: 1 | N825: 824 | O825: =_xlfn.XLOOKUP(Table4[[#This Row],[id]],VALINA[id],VALINA[name]) -> St. Helena | P825: =_xlfn.XLOOKUP(Table4[[#This Row],[id]],prov_color!A:A,prov_color!C:C) -> 6
A826: 825 | B826: America | C826: NWPacificSea | D826: Sea | E826: sea | G826: ncontinental | J826: Bering Straits | N826: 0 | O826: =_xlfn.XLOOKUP(Table4[[#This Row],[id]],VALINA[id],VALINA[name]) -> Bering Straits | P826: =_xlfn.XLOOKUP(Table4[[#This Row],[id]],prov_color!A:A,prov_color!C:C) -> 628
A827: 826 | B827: America | C827: AlaskaSea | D827: Sea | E827: sea | G827: tundra | J827: Aleutian Sea | N827: 0 | O827: =_xlfn.XLOOKUP(Table4[[#This Row],[id]],VALINA[id],VALINA[name]) -> Aleutian Sea | P827: =_xlfn.XLOOKUP(Table4[[#This Row],[id]],prov_color!A:A,prov_color!C:C) -> 419
A828: 827 | B828: America | C828: AlaskaSea | D828: Sea | E828: sea | G828: tundra | J828: Aleutian Islands | N828: 0 | O828: =_xlfn.XLOOKUP(Table4[[#This Row],[id]],VALINA[id],VALINA[name]) -> Aleutian Islands | P828: =_xlfn.XLOOKUP(Table4[[#This Row],[id]],prov_color!A:A,prov_color!C:C) -> 190
A829: 828 | B829: America | C829: AlaskaSea | D829: Sea | E829: sea | J829: Gulf of Alaska | K829: 0 | N829: 828 | O829: =_xlfn.XLOOKUP(Table4[[#This Row],[id]],VALINA[id],VALINA[name]) -> Gulf of Alaska | P829: =_xlfn.XLOOKUP(Table4[[#This Row],[id]],prov_color!A:A,prov_color!C:C) -> 218
A830: 829 | B830: America | C830: HudsonBaySea | D830: HudsonBayArea | E830: sea | J830: Hudson Bay | K830: 0 | N830: 829 | O830: =_xlfn.XLOOKUP(Table4[[#This Row],[id]],VALINA[id],VALINA[name]) -> Hudson Bay | P830: =_xlfn.XLOOKUP(Table4[[#This Row],[id]],prov_color!A:A,prov_color!C:C) -> 353
A831: 830 | B831: America | C831: HudsonBaySea | D831: Sea | E831: sea | J831: Hudson Straits | K831: 0 | N831: 830 | O831: =_xlfn.XLOOKUP(Table4[[#This Row],[id]],VALINA[id],VALINA[name]) -> Hudson Straits | P831: =_xlfn.XLOOKUP(Table4[[#This Row],[id]],prov_color!A:A,prov_color!C:C) -> 242
A832: 831 | B832: America | C832: HudsonBaySea | D832: Sea | E832: sea | J832: Sea of Baffin | K832: 0 | N832: 831 | O832: =_xlfn.XLOOKUP(Table4[[#This Row],[id]],VALINA[id],VALINA[name]) -> Sea of Baffin | P832: =_xlfn.XLOOKUP(Table4[[#This Row],[id]],prov_color!A:A,prov_color!C:C) -> 350
A833: 832 | B833: America | C833: HudsonBaySea | D833: Sea | E833: sea | J833: Strait of Labrador | K833: 0 | N833: 832 | O833: =_xlfn.XLOOKUP(Table4[[#This Row],[id]],VALINA[id],VALINA[name]) -> Strait of Labrador | P833: =_xlfn.XLOOKUP(Table4[[#This Row],[id]],prov_color!A:A,prov_color!C:C) -> 233
A834: 833 | B834: America | C834: HudsonBaySea | D834: Sea | E834: sea | J834: Gulf of Saint Lawrence | K834: 0 | N834: 833 | O834: =_xlfn.XLOOKUP(Table4[[#This Row],[id]],VALINA[id],VALINA[name]) -> Gulf of Saint Lawrence | P834: =_xlfn.XLOOKUP(Table4[[#This Row],[id]],prov_color!A:A,prov_color!C:C) -> 101
A835: 834 | B835: America | C835: HudsonBaySea | D835: Sea | E835: sea | J835: Sea of Labrador | K835: 0 | N835: 834 | O835: =_xlfn.XLOOKUP(Table4[[#This Row],[id]],VALINA[id],VALINA[name]) -> Sea of Labrador | P835: =_xlfn.XLOOKUP(Table4[[#This Row],[id]],prov_color!A:A,prov_color!C:C) -> 354
A836: 835 | B836: America | C836: ArcticSeaSea | D836: Sea | E836: sea | J836: Coast of Greenland | K836: 0 | N836: 835 | O836: =_xlfn.XLOOKUP(Table4[[#This Row],[id]],VALINA[id],VALINA[name]) -> Coast of Greenland | P836: =_xlfn.XLOOKUP(Table4[[#This Row],[id]],prov_color!A:A,prov_color!C:C) -> 607
A837: 836 | B837: Europe | C837: ArcticSeaSea | D837: Sea | E837: sea | J837: Coast of Iceland | K837: 0 | N837: 836 | O837: =_xlfn.XLOOKUP(Table4[[#This Row],[id]],VALINA[id],VALINA[name]) -> Coast of Iceland | P837: =_xlfn.XLOOKUP(Table4[[#This Row],[id]],prov_color!A:A,prov_color!C:C) -> 428
A838: 837 | B838: Europe | C838: ArcticSeaSea | D838: Sea | E838: sea | J838: Icelandic Sea | K838: 0 | N838: 837 | O838: =_xlfn.XLOOKUP(Table4[[#This Row],[id]],VALINA[id],VALINA[name]) -> Icelandic Sea | P838: =_xlfn.XLOOKUP(Table4[[#This Row],[id]],prov_color!A:A,prov_color!C:C) -> 389
A839: 838 | B839: Europe | C839: ArcticSeaSea | D839: Sea | E839: sea | J839: Jan Mayen Sea | K839: 0 | N839: 838 | O839: =_xlfn.XLOOKUP(Table4[[#This Row],[id]],VALINA[id],VALINA[name]) -> Jan Mayen Sea | P839: =_xlfn.XLOOKUP(Table4[[#This Row],[id]],prov_color!A:A,prov_color!C:C) -> 410
A840: 839 | B840: Europe | C840: ArcticSeaSea | D840: Sea | E840: sea | J840: Spitzberg | K840: 0 | N840: 839 | O840: =_xlfn.XLOOKUP(Table4[[#This Row],[id]],VALINA[id],VALINA[name]) -> Spitzberg | P840: =_xlfn.XLOOKUP(Table4[[#This Row],[id]],prov_color!A:A,prov_color!C:C) -> 472
A841: 840 | B841: Europe | C841: ArcticSeaSea | D841: Sea | E841: sea | J841: Throndheim Fjord | K841: 0 | N841: 840 | O841: =_xlfn.XLOOKUP(Table4[[#This Row],[id]],VALINA[id],VALINA[name]) -> Throndheim Fjord | P841: =_xlfn.XLOOKUP(Table4[[#This Row],[id]],prov_color!A:A,prov_color!C:C) -> 81
A842: 841 | B842: Europe | C842: ArcticSeaSea | D842: Sea | E842: sea | J842: The Lofotens | N842: 0 | O842: =_xlfn.XLOOKUP(Table4[[#This Row],[id]],VALINA[id],VALINA[name]) -> The Lofotens | P842: =_xlfn.XLOOKUP(Table4[[#This Row],[id]],prov_color!A:A,prov_color!C:C) -> 69
A843: 842 | B843: Europe | C843: ArcticSeaSea | D843: Sea | E843: sea | J843: North Cape | K843: 0 | N843: 842 | O843: =_xlfn.XLOOKUP(Table4[[#This Row],[id]],VALINA[id],VALINA[name]) -> North Cape | P843: =_xlfn.XLOOKUP(Table4[[#This Row],[id]],prov_color!A:A,prov_color!C:C) -> 190
A844: 843 | B844: Europe | C844: ArcticSeaSea | D844: Sea | E844: sea | G844: arctic | J844: White Sea | K844: 0 | N844: 843 | O844: =_xlfn.XLOOKUP(Table4[[#This Row],[id]],VALINA[id],VALINA[name]) -> White Sea | P844: =_xlfn.XLOOKUP(Table4[[#This Row],[id]],prov_color!A:A,prov_color!C:C) -> 402
A845: 844 | B845: Asia | C845: KamtchatkaSea | D845: Sea | E845: sea | J845: Bay of Ajan | K845: 0 | N845: 844 | O845: =_xlfn.XLOOKUP(Table4[[#This Row],[id]],VALINA[id],VALINA[name]) -> Bay of Ajan | P845: =_xlfn.XLOOKUP(Table4[[#This Row],[id]],prov_color!A:A,prov_color!C:C) -> 77
A846: 845 | B846: Asia | C846: KamtchatkaSea | D846: Sea | E846: sea | J846: Bay of Magadan | K846: 0 | N846: 845 | O846: =_xlfn.XLOOKUP(Table4[[#This Row],[id]],VALINA[id],VALINA[name]) -> Bay of Magadan | P846: =_xlfn.XLOOKUP(Table4[[#This Row],[id]],prov_color!A:A,prov_color!C:C) -> 70
A847: 846 | B847: Asia | C847: KamtchatkaSea | D847: Sea | E847: sea | J847: Gulf of Kolyma | K847: 0 | N847: 846 | O847: =_xlfn.XLOOKUP(Table4[[#This Row],[id]],VALINA[id],VALINA[name]) -> Gulf of kolyma | P847: =_xlfn.XLOOKUP(Table4[[#This Row],[id]],prov_color!A:A,prov_color!C:C) -> 82
A848: 847 | B848: Asia | C848: KamtchatkaSea | D848: Sea | E848: sea | J848: Bay of Kamenskoie | K848: 0 | N848: 847 | O848: =_xlfn.XLOOKUP(Table4[[#This Row],[id]],VALINA[id],VALINA[name]) -> Bay of Kamenskoie | P848: =_xlfn.XLOOKUP(Table4[[#This Row],[id]],prov_color!A:A,prov_color!C:C) -> 118
A849: 848 | B849: Asia | C849: KamtchatkaSea | D849: Sea | E849: sea | J849: Coast of Kamchatska | K849: 0 | N849: 848 | O849: =_xlfn.XLOOKUP(Table4[[#This Row],[id]],VALINA[id],VALINA[name]) -> Coast of Kamchatska | P849: =_xlfn.XLOOKUP(Table4[[#This Row],[id]],prov_color!A:A,prov_color!C:C) -> 159
A850: 849 | B850: Asia | C850: KamtchatkaSea | D850: Sea | E850: sea | J850: Cape of Kamchatska | K850: 0 | N850: 849 | O850: =_xlfn.XLOOKUP(Table4[[#This Row],[id]],VALINA[id],VALINA[name]) -> Cape of Kamchatska | P850: =_xlfn.XLOOKUP(Table4[[#This Row],[id]],prov_color!A:A,prov_color!C:C) -> 136
A851: 850 | B851: Asia | C851: KamtchatkaSea | D851: Sea | E851: sea | J851: Komandorski Islands | K851: 0 | N851: 850 | O851: =_xlfn.XLOOKUP(Table4[[#This Row],[id]],VALINA[id],VALINA[name]) -> Komandorski Islands | P851: =_xlfn.XLOOKUP(Table4[[#This Row],[id]],prov_color!A:A,prov_color!C:C) -> 130
...

Sheet provsorg
A1: id | B1: continent | C1: region | D1: area | E1: terrain | F1: religion | G1: climate | H1: culture | I1: goods | J1: name | K1: colonization_difficulty | L1: income | M1: manpower | N1: size_modifier | O1: map tiles | P1: map id | Q1: TRANS
A2: 1 | B2: America | C2: North America | D2: Alaska | E2: mountain | F2: pagan | G2: arctic | H2: inuit | I2: gold | J2: Yukon | K2: 9 | L2: 1 | M2: 1 | N2: 0 | O2: =_xlfn.XLOOKUP(VALINA[[#This Row],[id]],prov_color!A:A,prov_color!C:C) -> 65 | P2: =_xlfn.XLOOKUP(VALINA[[#This Row],[id]],Table4[id],Table4[name]) -> Yukon | Q2: =_xlfn.XLOOKUP(VALINA[[#This Row],[name]],Trans!A:A,Trans!B:B) -> Yukon
A3: 2 | B3: America | C3: North America | D3: Alaska | E3: mountain | F3: pagan | G3: arctic | H3: inuit | I3: fur | J3: Kitimat | K3: 8 | L3: 1 | M3: 1 | N3: 0 | O3: =_xlfn.XLOOKUP(VALINA[[#This Row],[id]],prov_color!A:A,prov_color!C:C) -> 23 | P3: =_xlfn.XLOOKUP(VALINA[[#This Row],[id]],Table4[id],Table4[name]) -> Kitimat | Q3: =_xlfn.XLOOKUP(VALINA[[#This Row],[name]],Trans!A:A,Trans!B:B) -> Kitimat
A4: 3 | B4: America | C4: North America | D4: Alaska | E4: forest | F4: pagan | G4: arctic | H4: salishan | I4: fur | J4: Sitka | K4: 7 | L4: 1 | M4: 1 | N4: 0 | O4: =_xlfn.XLOOKUP(VALINA[[#This Row],[id]],prov_color!A:A,prov_color!C:C) -> 76 | P4: =_xlfn.XLOOKUP(VALINA[[#This Row],[id]],Table4[id],Table4[name]) -> Sitka | Q4: =_xlfn.XLOOKUP(VALINA[[#This Row],[name]],Trans!A:A,Trans!B:B) -> Sitka
A5: 4 | B5: America | C5: North America | D5: Oregon | E5: mountain | F5: pagan | G5: ncontinental | H5: salishan | I5: fish | J5: Nanaimo | K5: 7 | L5: 2 | M5: 1 | N5: 0 | O5: =_xlfn.XLOOKUP(VALINA[[#This Row],[id]],prov_color!A:A,prov_color!C:C) -> 52 | P5: =_xlfn.XLOOKUP(VALINA[[#This Row],[id]],Table4[id],Table4[name]) -> Nanaimo | Q5: =_xlfn.XLOOKUP(VALINA[[#This Row],[name]],Trans!A:A,Trans!B:B) -> Nanaimo
A6: 5 | B6: America | C6: North America | D6: Oregon | E6: mountain | F6: pagan | G6: ncontinental | H6: salishan | I6: naval_supplies | J6: Olympia | K6: 6 | L6: 3 | M6: 1 | N6: 0 | O6: =_xlfn.XLOOKUP(VALINA[[#This Row],[id]],prov_color!A:A,prov_color!C:C) -> 81 | P6: =_xlfn.XLOOKUP(VALINA[[#This Row],[id]],Table4[id],Table4[name]) -> Olympia | Q6: =_xlfn.XLOOKUP(VALINA[[#This Row],[name]],Trans!A:A,Trans!B:B) -> Olympia
A7: 6 | B7: America | C7: North America | D7: Oregon | E7: forest | F7: pagan | G7: ncontinental | H7: salishan | I7: fur | J7: Columbia | K7: 4 | L7: 5 | M7: 1 | N7: 0 | O7: =_xlfn.XLOOKUP(VALINA[[#This Row],[id]],prov_color!A:A,prov_color!C:C) -> 54 | P7: =_xlfn.XLOOKUP(VALINA[[#This Row],[id]],Table4[id],Table4[name]) -> Columbia | Q7: =_xlfn.XLOOKUP(VALINA[[#This Row],[name]],Trans!A:A,Trans!B:B) -> Columbia
A8: 7 | B8: America | C8: North America | D8: Oregon | E8: forest | F8: pagan | G8: ncontinental | H8: salishan | I8: fur | J8: Nehalem | K8: 5 | L8: 3 | M8: 1 | N8: 0 | O8: =_xlfn.XLOOKUP(VALINA[[#This Row],[id]],prov_color!A:A,prov_color!C:C) -> 45 | P8: =_xlfn.XLOOKUP(VALINA[[#This Row],[id]],Table4[id],Table4[name]) -> Nehalem | Q8: =_xlfn.XLOOKUP(VALINA[[#This Row],[name]],Trans!A:A,Trans!B:B) -> Nehalem
A9: 8 | B9: America | C9: North America | D9: California | E9: plains | F9: pagan | G9: temperate | H9: miwok | I9: wine | J9: Sacramento | K9: 2 | L9: 7 | M9: 2 | N9: 0 | O9: =_xlfn.XLOOKUP(VALINA[[#This Row],[id]],prov_color!A:A,prov_color!C:C) -> 45 | P9: =_xlfn.XLOOKUP(VALINA[[#This Row],[id]],Table4[id],Table4[name]) -> Sacramento | Q9: =_xlfn.XLOOKUP(VALINA[[#This Row],[name]],Trans!A:A,Trans!B:B) -> Sacramento
A10: 9 | B10: America | C10: North America | D10: California | E10: mountain | F10: pagan | G10: temperate | H10: miwok | I10: gold | J10: Monterey | K10: 4 | L10: 5 | M10: 1 | N10: 0 | O10: =_xlfn.XLOOKUP(VALINA[[#This Row],[id]],prov_color!A:A,prov_color!C:C) -> 37 | P10: =_xlfn.XLOOKUP(VALINA[[#This Row],[id]],Table4[id],Table4[name]) -> Monterey | Q10: =_xlfn.XLOOKUP(VALINA[[#This Row],[name]],Trans!A:A,Trans!B:B) -> Monterey
A11: 10 | B11: America | C11: North America | D11: California | E11: mountain | F11: pagan | G11: temperate | H11: takic | I11: wool | J11: Sierra Madre | K11: 4 | L11: 4 | M11: 1 | N11: 0 | O11: =_xlfn.XLOOKUP(VALINA[[#This Row],[id]],prov_color!A:A,prov_color!C:C) -> 40 | P11: =_xlfn.XLOOKUP(VALINA[[#This Row],[id]],Table4[id],Table4[name]) -> Sierra Madre | Q11: =_xlfn.XLOOKUP(VALINA[[#This Row],[name]],Trans!A:A,Trans!B:B) -> Sierra Madre
A12: 11 | B12: America | C12: North America | D12: California | E12: plains | F12: pagan | G12: temperate | H12: takic | I12: grain | J12: San Bernardino | K12: 3 | L12: 5 | M12: 2 | N12: 0 | O12: =_xlfn.XLOOKUP(VALINA[[#This Row],[id]],prov_color!A:A,prov_color!C:C) -> 53 | P12: =_xlfn.XLOOKUP(VALINA[[#This Row],[id]],Table4[id],Table4[name]) -> San Bernardino | Q12: =_xlfn.XLOOKUP(VALINA[[#This Row],[name]],Trans!A:A,Trans!B:B) -> San Bernardino
A13: 12 | B13: America | C13: Central America | D13: Sonora | E13: mountain | F13: pagan | G13: desertic | H13: hokan | I13: fish | J13: Ensenada | K13: 8 | L13: 1 | M13: 1 | N13: 0 | O13: =_xlfn.XLOOKUP(VALINA[[#This Row],[id]],prov_color!A:A,prov_color!C:C) -> 38 | P13: =_xlfn.XLOOKUP(VALINA[[#This Row],[id]],Table4[id],Table4[name]) -> Ensenada | Q13: =_xlfn.XLOOKUP(VALINA[[#This Row],[name]],Trans!A:A,Trans!B:B) -> Ensenada
... A825: 824 | B825: Africa | C825: West Africa | D825: St Helena | E825: mountain | F825: pagan | G825: temperate | H825: tehuelche | I825: fish | J825: St. Helena | K825: 3 | L825: 1 | M825: 1 | N825: 0 | O825: =_xlfn.XLOOKUP(VALINA[[#This Row],[id]],prov_color!A:A,prov_color!C:C) -> 6 | P825: =_xlfn.XLOOKUP(VALINA[[#This Row],[id]],Table4[id],Table4[name]) -> St. Helena | Q825: =_xlfn.XLOOKUP(VALINA[[#This Row],[name]],Trans!A:A,Trans!B:B) -> St. Helena
A826: 825 | B826: America | C826: NWPacificSea | D826: Sea | E826: sea | G826: ncontinental | J826: Bering Straits | N826: 0 | O826: =_xlfn.XLOOKUP(VALINA[[#This Row],[id]],prov_color!A:A,prov_color!C:C) -> 628 | P826: =_xlfn.XLOOKUP(VALINA[[#This Row],[id]],Table4[id],Table4[name]) -> Bering Straits | Q826: =_xlfn.XLOOKUP(VALINA[[#This Row],[name]],Trans!A:A,Trans!B:B) -> Bering Straits
A827: 826 | B827: America | C827: AlaskaSea | D827: Sea | E827: sea | G827: tundra | J827: Aleutian Sea | N827: 0 | O827: =_xlfn.XLOOKUP(VALINA[[#This Row],[id]],prov_color!A:A,prov_color!C:C) -> 419 | P827: =_xlfn.XLOOKUP(VALINA[[#This Row],[id]],Table4[id],Table4[name]) -> Aleutian Sea | Q827: =_xlfn.XLOOKUP(VALINA[[#This Row],[name]],Trans!A:A,Trans!B:B) -> Aleutian Sea
A828: 827 | B828: America | C828: AlaskaSea | D828: Sea | E828: sea | G828: tundra | J828: Aleutian Islands | N828: 0 | O828: =_xlfn.XLOOKUP(VALINA[[#This Row],[id]],prov_color!A:A,prov_color!C:C) -> 190 | P828: =_xlfn.XLOOKUP(VALINA[[#This Row],[id]],Table4[id],Table4[name]) -> Aleutian Islands | Q828: =_xlfn.XLOOKUP(VALINA[[#This Row],[name]],Trans!A:A,Trans!B:B) -> Aleutian Islands
A829: 828 | B829: America | C829: AlaskaSea | D829: Sea | E829: sea | G829: tundra | J829: Gulf of Alaska | N829: 0 | O829: =_xlfn.XLOOKUP(VALINA[[#This Row],[id]],prov_color!A:A,prov_color!C:C) -> 218 | P829: =_xlfn.XLOOKUP(VALINA[[#This Row],[id]],Table4[id],Table4[name]) -> Gulf of Alaska | Q829: =_xlfn.XLOOKUP(VALINA[[#This Row],[name]],Trans!A:A,Trans!B:B) -> Gulf of Alaska
A830: 829 | B830: America | C830: HudsonBaySea | D830: HudsonBayArea | E830: sea | G830: tundra | J830: Hudson Bay | N830: 0 | O830: =_xlfn.XLOOKUP(VALINA[[#This Row],[id]],prov_color!A:A,prov_color!C:C) -> 353 | P830: =_xlfn.XLOOKUP(VALINA[[#This Row],[id]],Table4[id],Table4[name]) -> Hudson Bay | Q830: =_xlfn.XLOOKUP(VALINA[[#This Row],[name]],Trans!A:A,Trans!B:B) -> Hudson Bay
A831: 830 | B831: America | C831: HudsonBaySea | D831: Sea | E831: sea | G831: tundra | J831: Hudson Straits | N831: 0 | O831: =_xlfn.XLOOKUP(VALINA[[#This Row],[id]],prov_color!A:A,prov_color!C:C) -> 242 | P831: =_xlfn.XLOOKUP(VALINA[[#This Row],[id]],Table4[id],Table4[name]) -> Hudson Straits | Q831: =_xlfn.XLOOKUP(VALINA[[#This Row],[name]],Trans!A:A,Trans!B:B) -> Hudson Straits
A832: 831 | B832: America | C832: HudsonBaySea | D832: Sea | E832: sea | G832: tundra | J832: Sea of Baffin | N832: 0 | O832: =_xlfn.XLOOKUP(VALINA[[#This Row],[id]],prov_color!A:A,prov_color!C:C) -> 350 | P832: =_xlfn.XLOOKUP(VALINA[[#This Row],[id]],Table4[id],Table4[name]) -> Sea of Baffin | Q832: =_xlfn.XLOOKUP(VALINA[[#This Row],[name]],Trans!A:A,Trans!B:B) -> Sea of Baffin
A833: 832 | B833: America | C833: HudsonBaySea | D833: Sea | E833: sea | G833: ncontinental | J833: Strait of Labrador | N833: 0 | O833: =_xlfn.XLOOKUP(VALINA[[#This Row],[id]],prov_color!A:A,prov_color!C:C) -> 233 | P833: =_xlfn.XLOOKUP(VALINA[[#This Row],[id]],Table4[id],Table4[name]) -> Strait of Labrador | Q833: =_xlfn.XLOOKUP(VALINA[[#This Row],[name]],Trans!A:A,Trans!B:B) -> Strait of Labrador
A834: 833 | B834: America | C834: HudsonBaySea | D834: Sea | E834: sea | J834: Gulf of Saint Lawrence | N834: 0 | O834: =_xlfn.XLOOKUP(VALINA[[#This Row],[id]],prov_color!A:A,prov_color!C:C) -> 101 | P834: =_xlfn.XLOOKUP(VALINA[[#This Row],[id]],Table4[id],Table4[name]) -> Gulf of Saint Lawrence | Q834: =_xlfn.XLOOKUP(VALINA[[#This Row],[name]],Trans!A:A,Trans!B:B) -> Gulf of Saint Lawrence
A835: 834 | B835: America | C835: HudsonBaySea | D835: Sea | E835: sea | G835: ncontinental | J835: Sea of Labrador | N835: 0 | O835: =_xlfn.XLOOKUP(VALINA[[#This Row],[id]],prov_color!A:A,prov_color!C:C) -> 354 | P835: =_xlfn.XLOOKUP(VALINA[[#This Row],[id]],Table4[id],Table4[name]) -> Sea of Labrador | Q835: =_xlfn.XLOOKUP(VALINA[[#This Row],[name]],Trans!A:A,Trans!B:B) -> Sea of Labrador
A836: 835 | B836: America | C836: ArcticSeaSea | D836: Sea | E836: sea | G836: ncontinental | J836: Coast of Greenland | N836: 0 | O836: =_xlfn.XLOOKUP(VALINA[[#This Row],[id]],prov_color!A:A,prov_color!C:C) -> 607 | P836: =_xlfn.XLOOKUP(VALINA[[#This Row],[id]],Table4[id],Table4[name]) -> Coast of Greenland | Q836: =_xlfn.XLOOKUP(VALINA[[#This Row],[name]],Trans!A:A,Trans!B:B) -> Coast of Greenland
A837: 836 | B837: Europe | C837: ArcticSeaSea | D837: Sea | E837: sea | J837: Coast of Iceland | N837: 0 | O837: =_xlfn.XLOOKUP(VALINA[[#This Row],[id]],prov_color!A:A,prov_color!C:C) -> 428 | P837: =_xlfn.XLOOKUP(VALINA[[#This Row],[id]],Table4[id],Table4[name]) -> Coast of Iceland | Q837: =_xlfn.XLOOKUP(VALINA[[#This Row],[name]],Trans!A:A,Trans!B:B) -> Coast of Iceland
A838: 837 | B838: Europe | C838: ArcticSeaSea | D838: Sea | E838: sea | G838: ncontinental | J838: Icelandic Sea | N838: 0 | O838: =_xlfn.XLOOKUP(VALINA[[#This Row],[id]],prov_color!A:A,prov_color!C:C) -> 389 | P838: =_xlfn.XLOOKUP(VALINA[[#This Row],[id]],Table4[id],Table4[name]) -> Icelandic Sea | Q838: =_xlfn.XLOOKUP(VALINA[[#This Row],[name]],Trans!A:A,Trans!B:B) -> Icelandic Sea
A839: 838 | B839: Europe | C839: ArcticSeaSea | D839: Sea | E839: sea | G839: ncontinental | J839: Jan Mayen Sea | N839: 0 | O839: =_xlfn.XLOOKUP(VALINA[[#This Row],[id]],prov_color!A:A,prov_color!C:C) -> 410 | P839: =_xlfn.XLOOKUP(VALINA[[#This Row],[id]],Table4[id],Table4[name]) -> Jan Mayen Sea | Q839: =_xlfn.XLOOKUP(VALINA[[#This Row],[name]],Trans!A:A,Trans!B:B) -> Jan Mayen Sea
A840: 839 | B840: Europe | C840: ArcticSeaSea | D840: Sea | E840: sea | G840: ncontinental | J840: Spitzberg | N840: 0 | O840: =_xlfn.XLOOKUP(VALINA[[#This Row],[id]],prov_color!A:A,prov_color!C:C) -> 472 | P840: =_xlfn.XLOOKUP(VALINA[[#This Row],[id]],Table4[id],Table4[name]) -> Spitzberg | Q840: =_xlfn.XLOOKUP(VALINA[[#This Row],[name]],Trans!A:A,Trans!B:B) -> Spitzberg
A841: 840 | B841: Europe | C841: ArcticSeaSea | D841: Sea | E841: sea | J841: Throndheim Fjord | N841: 0 | O841: =_xlfn.XLOOKUP(VALINA[[#This Row],[id]],prov_color!A:A,prov_color!C:C) -> 81 | P841: =_xlfn.XLOOKUP(VALINA[[#This Row],[id]],Table4[id],Table4[name]) -> Throndheim Fjord | Q841: =_xlfn.XLOOKUP(VALINA[[#This Row],[name]],Trans!A:A,Trans!B:B) -> Throndheim Fjord
A842: 841 | B842: Europe | C842: ArcticSeaSea | D842: Sea | E842: sea | J842: The Lofotens | N842: 0 | O842: =_xlfn.XLOOKUP(VALINA[[#This Row],[id]],prov_color!A:A,prov_color!C:C) -> 69 | P842: =_xlfn.XLOOKUP(VALINA[[#This Row],[id]],Table4[id],Table4[name]) -> The Lofotens | Q842: =_xlfn.XLOOKUP(VALINA[[#This Row],[name]],Trans!A:A,Trans!B:B) -> The Lofotens
A843: 842 | B843: Europe | C843: ArcticSeaSea | D843: Sea | E843: sea | G843: ncontinental | J843: North Cape | N843: 0 | O843: =_xlfn.XLOOKUP(VALINA[[#This Row],[id]],prov_color!A:A,prov_color!C:C) -> 190 | P843: =_xlfn.XLOOKUP(VALINA[[#This Row],[id]],Table4[id],Table4[name]) -> North Cape | Q843: =_xlfn.XLOOKUP(VALINA[[#This Row],[name]],Trans!A:A,Trans!B:B) -> North Cape
A844: 843 | B844: Europe | C844: ArcticSeaSea | D844: Sea | E844: sea | G844: tundra | J844: White Sea | N844: 0 | O844: =_xlfn.XLOOKUP(VALINA[[#This Row],[id]],prov_color!A:A,prov_color!C:C) -> 402 | P844: =_xlfn.XLOOKUP(VALINA[[#This Row],[id]],Table4[id],Table4[name]) -> White Sea | Q844: =_xlfn.XLOOKUP(VALINA[[#This Row],[name]],Trans!A:A,Trans!B:B) -> White Sea
A845: 844 | B845: Asia | C845: KamtchatkaSea | D845: Sea | E845: sea | G845: ncontinental | J845: Bay of Ajan | N845: 0 | O845: =_xlfn.XLOOKUP(VALINA[[#This Row],[id]],prov_color!A:A,prov_color!C:C) -> 77 | P845: =_xlfn.XLOOKUP(VALINA[[#This Row],[id]],Table4[id],Table4[name]) -> Bay of Ajan | Q845: =_xlfn.XLOOKUP(VALINA[[#This Row],[name]],Trans!A:A,Trans!B:B) -> Bay of Ajan
A846: 845 | B846: Asia | C846: KamtchatkaSea | D846: Sea | E846: sea | G846: ncontinental | J846: Bay of Magadan | N846: 0 | O846: =_xlfn.XLOOKUP(VALINA[[#This Row],[id]],prov_color!A:A,prov_color!C:C) -> 70 | P846: =_xlfn.XLOOKUP(VALINA[[#This Row],[id]],Table4[id],Table4[name]) -> Bay of Magadan | Q846: =_xlfn.XLOOKUP(VALINA[[#This Row],[name]],Trans!A:A,Trans!B:B) -> Bay of Magadan
A847: 846 | B847: Asia | C847: KamtchatkaSea | D847: Sea | E847: sea | G847: ncontinental | J847: Gulf of kolyma | N847: 0 | O847: =_xlfn.XLOOKUP(VALINA[[#This Row],[id]],prov_color!A:A,prov_color!C:C) -> 82 | P847: =_xlfn.XLOOKUP(VALINA[[#This Row],[id]],Table4[id],Table4[name]) -> Gulf of Kolyma | Q847: =_xlfn.XLOOKUP(VALINA[[#This Row],[name]],Trans!A:A,Trans!B:B) -> Gulf of Kolyma
A848: 847 | B848: Asia | C848: KamtchatkaSea | D848: Sea | E848: sea | G848: tundra | J848: Bay of Kamenskoie | N848: 0 | O848: =_xlfn.XLOOKUP(VALINA[[#This Row],[id]],prov_color!A:A,prov_color!C:C) -> 118 | P848: =_xlfn.XLOOKUP(VALINA[[#This Row],[id]],Table4[id],Table4[name]) -> Bay of Kamenskoie | Q848: =_xlfn.XLOOKUP(VALINA[[#This Row],[name]],Trans!A:A,Trans!B:B) -> Bay of Kamenskoie
A849: 848 | B849: Asia | C849: KamtchatkaSea | D849: Sea | E849: sea | G849: ncontinental | J849: Coast of Kamchatska | N849: 0 | O849: =_xlfn.XLOOKUP(VALINA[[#This Row],[id]],prov_color!A:A,prov_color!C:C) -> 159 | P849: =_xlfn.XLOOKUP(VALINA[[#This Row],[id]],Table4[id],Table4[name]) -> Coast of Kamchatska | Q849: =_xlfn.XLOOKUP(VALINA[[#This Row],[name]],Trans!A:A,Trans!B:B) -> Coast of Kamchatska
A850: 849 | B850: Asia | C850: KamtchatkaSea | D850: Sea | E850: sea | J850: Cape of Kamchatska | N850: 0 | O850: =_xlfn.XLOOKUP(VALINA[[#This Row],[id]],prov_color!A:A,prov_color!C:C) -> 136 | P850: =_xlfn.XLOOKUP(VALINA[[#This Row],[id]],Table4[id],Table4[name]) -> Cape of Kamchatska | Q850: =_xlfn.XLOOKUP(VALINA[[#This Row],[name]],Trans!A:A,Trans!B:B) -> Cape of Kamchatska
A851: 850 | B851: Asia | C851: KamtchatkaSea | D851: Sea | E851: sea | J851: Komandorski Islands | N851: 0 | O851: =_xlfn.XLOOKUP(VALINA[[#This Row],[id]],prov_color!A:A,prov_color!C:C) -> 130 | P851: =_xlfn.XLOOKUP(VALINA[[#This Row],[id]],Table4[id],Table4[name]) -> Komandorski Islands | Q851: =_xlfn.XLOOKUP(VALINA[[#This Row],[name]],Trans!A:A,Trans!B:B) -> Komandorski Islands
...

Sheet Trans
A1: #Provinces | B1: x
A2: Acadie | B2: Acadie | C2: x
A3: Acapulco Bay | B3: Acapulco Bay | C3: x
A4: Accra | B4: Accra | C4: x
A5: Adana | B5: Adana | C5: x
A6: Aden | B6: Aden | C6: x
A7: Adirondak | B7: Adirondak | C7: x
A8: Adriatic Sea | B8: Adriatic Sea | C8: x
A9: Aegean Sea | B9: Aegean Sea | C9: x
A10: Afars | B10: Afars | C10: x
A11: Ahwaz | B11: Awhaz | C11: x
A12: Aires | B12: Aires | C12: x
A13: Aisen | B13: Aisen | C13: x
... A1455: Zimbabwe | B1455: Zimbabwe | C1455: x
A1456: # | B1456: x
A1457: Terra Incognita | B1457: Terra Incognita | C1457: x
A1458: # | B1458: x
A1459: #----------------------------------------------------------------------------------------------- | B1459: x
A1460: # | B1460: x
A1461: Acadie | B1461: Fundy | C1461: x
A1462: Accra | B1462: Edo | C1462: x
A1463: Adana | B1463: Alexandretta | C1463: x
A1464: Aden | B1464: Aden | C1464: x
A1465: Adirondak | B1465: Adirondak | C1465: x
A1466: Afars | B1466: Tadjourah | C1466: x
A1467: Ahwaz | B1467: Abadan | C1467: x
A1468: Aires | B1468: Aires | C1468: x
A1469: Aisen | B1469: Aisen | C1469: x
A1470: Ajeh | B1470: Kutaraja | C1470: x
A1471: Al Djazair | B1471: Algiers | C1471: x
A1472: Al Kharam | B1472: Suhar | C1472: x
... A2429: Zimbabwe | B2429: Zimbabwe | C2429: x
A2430: # | B2430: x
A2431: #----------------------------------------------------------------------------------------------- | B2431: x
A2432: #EOF | B2432: x

Sheet prov_color
A1: ID | B1: hex | C1: count | J1: ID | K1: hex | L1: count
A2: 1 | B2: #172f47 | C2: 65 | J2: 1 | K2: #172f47 | L2: 65
A3: 2 | B3: #2e5e8f | C3: 23 | J3: 2 | K3: #2e5e8f | L3: 23
A4: 3 | B4: #458ed7 | C4: 76 | J4: 3 | K4: #458ed7 | L4: 76
A5: 4 | B5: #5cbd25 | C5: 52 | J5: 4 | K5: #5cbd25 | L5: 52
A6: 5 | B6: #73ed6c | C6: 81 | J6: 5 | K6: #73ed6c | L6: 81
A7: 6 | B7: #8a22b4 | C7: 54 | J7: 6 | K7: #8a22b4 | L7: 54
A8: 7 | B8: #a15202 | C8: 45 | J8: 7 | K8: #a15202 | L8: 45
A9: 8 | B9: #b8814a | C9: 45 | J9: 8 | K9: #b8814a | L9: 45
A10: 9 | B10: #d0b192 | C10: 37 | J10: 9 | K10: #d0b192 | L10: 37
A11: 10 | B11: #e7e0d9 | C11: 40 | J11: 10 | K11: #e7e0d9 | L11: 40
A12: 11 | B12: #041627 | C12: 53 | J12: 11 | K12: #041627 | L12: 53
A13: 12 | B13: #1b456f | C13: 38 | J13: 12 | K13: #1b456f | L13: 38
... A4000: 3999 | B4000: #da1a54 | C4000: 0 | J4000: 3999 | K4000: #da1a54 | L4000: 0

Sheet provsagcp
A1: id | B1: continent | C1: region | D1: area | E1: terrain | F1: religion | G1: climate | H1: culture | I1: goods | J1: name | K1: colonization_difficulty | L1: income | M1: manpower | N1: size_modifier
A2: 0 | E2: terra_incognita | J2: Terra Incognita | Q2: {=_xlfn.UNIQUE(AGCEEP[continent])} -> 0 | R2: {=_xlfn.UNIQUE(AGCEEP[region])} -> 0 | S2: {=_xlfn.UNIQUE(AGCEEP[area])} -> 0 | T2: {=_xlfn.UNIQUE(AGCEEP[terrain])} -> terra_incognita | U2: {=_xlfn.UNIQUE(AGCEEP[religion])} -> 0 | V2: {=_xlfn.UNIQUE(AGCEEP[climate])} -> 0 | W2: {=_xlfn.UNIQUE(AGCEEP[culture])} -> 0 | X2: {=_xlfn.UNIQUE(AGCEEP[goods])} -> 0
A3: 1 | B3: America | C3: North America | D3: Alaska | E3: mountain | F3: pagan | G3: arctic | H3: inuit | I3: fur | J3: Yukon | K3: 9 | L3: 1 | M3: 1 | N3: 0 | Q3: America | R3: North America | S3: Alaska | T3: mountain | U3: pagan | V3: arctic | W3: inuit | X3: fur
A4: 2 | B4: America | C4: North America | D4: Alaska | E4: mountain | F4: pagan | G4: arctic | H4: inuit | I4: fur | J4: Kitimat | K4: 8 | L4: 1 | M4: 1 | N4: 0 | Q4: Europe | R4: Central America | S4: Oregon | T4: forest | U4: catholic | V4: ncontinental | W4: navajo | X4: wine
A5: 3 | B5: America | C5: North America | D5: Alaska | E5: forest | F5: pagan | G5: arctic | H5: inuit | I5: fur | J5: Sitka | K5: 7 | L5: 1 | M5: 1 | N5: 0 | Q5: Asia | R5: Caribbean | S5: California | T5: plains | U5: orthodox | V5: temperate | W5: aztec | X5: wool
A6: 4 | B6: America | C6: North America | D6: Oregon | E6: mountain | F6: pagan | G6: ncontinental | H6: navajo | I6: fur | J6: Nanaimo | K6: 7 | L6: 2 | M6: 1 | N6: 0 | Q6: Oceania | R6: South America | S6: Sonora | T6: desert | U6: sunni | V6: desertic | W6: zapotec | X6: salt
A7: 5 | B7: America | C7: North America | D7: Oregon | E7: mountain | F7: pagan | G7: ncontinental | H7: navajo | I7: fur | J7: Olympia | K7: 6 | L7: 3 | M7: 1 | N7: 0 | Q7: Africa | R7: British Isles | S7: Nevada | T7: marsh | U7: miaphysite | V7: tropical | W7: mayan | X7: gold
A8: 6 | B8: America | C8: North America | D8: Oregon | E8: forest | F8: pagan | G8: ncontinental | H8: navajo | I8: fur | J8: Columbia | K8: 4 | L8: 5 | M8: 1 | N8: 0 | R8: Scandinavia | S8: Azteca | T8: sea | U8: shia | V8: tundra | W8: mesoamerican | X8: grain
A9: 7 | B9: America | C9: North America | D9: Oregon | E9: forest | F9: pagan | G9: ncontinental | H9: navajo | I9: fur | J9: Nehalem | K9: 5 | L9: 3 | M9: 1 | N9: 0 | R9: Eastern Europe | S9: Costa Rica | T9: river | U9: hindu | V9: scontinental | W9: creek | X9: sugar
A10: 8 | B10: America | C10: North America | D10: California | E10: plains | F10: pagan | G10: temperate | H10: navajo | I10: wine | J10: Sacramento | K10: 2 | L10: 7 | M10: 2 | N10: 0 | R10: HRE | S10: Panama | U10: buddhist | W10: cherokee | X10: fish
A11: 9 | B11: America | C11: North America | D11: California | E11: mountain | F11: pagan | G11: temperate | H11: navajo | I11: wine | J11: Monterey | K11: 4 | L11: 5 | M11: 1 | N11: 0 | R11: Central Europe | S11: Texas | U11: confucian | W11: native | X11: chinaware
A12: 10 | B12: America | C12: North America | D12: California | E12: mountain | F12: pagan | G12: temperate | H12: navajo | I12: wool | J12: Sierra Madre | K12: 4 | L12: 4 | M12: 1 | N12: 0 | R12: Western Europe | S12: Louisiane | U12: shinto | W12: shawnee | X12: naval_supplies
A13: 11 | B13: America | C13: North America | D13: California | E13: desert | F13: pagan | G13: temperate | H13: navajo | I13: wool | J13: San Bernardino | K13: 3 | L13: 5 | M13: 2 | N13: 0 | R13: Southern Europe | S13: Florida | W13: iroquis | X13: cotton
A14: 12 | B14: America | C14: Central America | D14: Sonora | E14: mountain | F14: pagan | G14: desertic | H14: navajo | I14: wool | J14: Ensenada | K14: 8 | L14: 1 | M14: 1 | N14: 0 | R14: Middle East | S14: Georgia | W14: dakota | X14: tobacco
A15: 13 | B15: America | C15: Central America | D15: Sonora | E15: mountain | F15: pagan | G15: desertic | H15: navajo | I15: wool | J15: Baja | K15: 8 | L15: 1 | M15: 1 | N15: 0 | R15: Central Asia | S15: Kansas | W15: huron | X15: iron
A16: 14 | B16: America | C16: North America | D16: Nevada | E16: desert | F16: pagan | G16: desertic | H16: navajo | I16: salt | J16: Salton | K16: 9 | L16: 1 | M16: 1 | N16: 0 | R16: Siberia | S16: Illinois | W16: abenaki | X16: copper
A17: 15 | B17: America | C17: Central America | D17: Sonora | E17: desert | F17: pagan | G17: desertic | H17: navajo | I17: gold | J17: Altar | K17: 6 | L17: 1 | M17: 1 | N17: 0 | R17: India | S17: Appalachia | W17: cree | X17: coffee
A18: 16 | B18: America | C18: North America | D18: Nevada | E18: desert | F18: pagan | G18: desertic | H18: navajo | I18: wool | J18: Canyon | K18: 9 | L18: 1 | M18: 1 | N18: 0 | R18: China | S18: Ohio | W18: caribbean | X18: spices
A19: 17 | B19: America | C19: Central America | D19: Sonora | E19: desert | F19: pagan | G19: desertic | H19: navajo | I19: wool | J19: Empalme | K19: 7 | L19: 1 | M19: 1 | N19: 0 | R19: Korea | S19: Grand Lacs | W19: guajiro | X19: nothing
A20: 18 | B20: America | C20: North America | D20: Nevada | E20: mountain | F20: pagan | G20: desertic | H20: navajo | I20: wool | J20: Arizona | K20: 9 | L20: 1 | M20: 1 | N20: 0 | R20: Indochina | S20: Plaines | W20: andean | X20: slaves
A21: 19 | B21: America | C21: North America | D21: Nevada | E21: mountain | F21: pagan | G21: temperate | H21: navajo | I21: wool | J21: Pinalero | K21: 8 | L21: 1 | M21: 1 | N21: 0 | R21: Indonesia | S21: Maine | W21: teremembe | X21: cloth
A22: 20 | B22: America | C22: Central America | D22: Sonora | E22: desert | F22: pagan | G22: desertic | H22: navajo | I22: wool | J22: Chihuahua | K22: 7 | L22: 1 | M22: 1 | N22: 0 | R22: Japan | S22: Quebec | W22: tupinamba | X22: tea
A23: 21 | B23: America | C23: Central America | D23: Sonora | E23: mountain | F23: pagan | G23: desertic | H23: navajo | I23: grain | J23: Mazatlan | K23: 7 | L23: 1 | M23: 1 | N23: 0 | R23: Australia | S23: Acadie | W23: mataco | X23: ivory
A24: 22 | B24: America | C24: North America | D24: Nevada | E24: plains | F24: pagan | G24: temperate | H24: navajo | I24: wool | J24: El Paso | K24: 7 | L24: 2 | M24: 1 | N24: 0 | R24: North Africa | S24: Newfoundland | W24: celtic
A25: 23 | B25: America | C25: Central America | D25: Sonora | E25: desert | F25: pagan | G25: desertic | H25: navajo | I25: wool | J25: Coahuilha | K25: 7 | L25: 1 | M25: 1 | N25: 0 | R25: East Africa | S25: Labrador | W25: english
A26: 24 | B26: America | C26: Central America | D26: Azteca | E26: mountain | F26: pagan | G26: temperate | H26: aztec | I26: gold | J26: Jalisco | K26: 3 | L26: 5 | M26: 1 | N26: 0 | R26: South Africa | S26: Hudson Bay | W26: scandinavian
A27: 25 | B27: America | C27: Central America | D27: Sonora | E27: plains | F27: pagan | G27: temperate | H27: aztec | I27: gold | J27: Saltillo | K27: 6 | L27: 2 | M27: 1 | N27: 0 | R27: West Africa | S27: Cuba | W27: ugric
A28: 26 | B28: America | C28: Central America | D28: Azteca | E28: mountain | F28: pagan | G28: temperate | H28: aztec | I28: gold | J28: Michoac�n | K28: 3 | L28: 7 | M28: 3 | N28: 0 | R28: Pacific | S28: Haiti | W28: russian
A29: 27 | B29: America | C29: Central America | D29: Azteca | E29: mountain | F29: pagan | G29: temperate | H29: aztec | I29: gold | J29: Zacatecas | K29: 3 | L29: 8 | M29: 3 | N29: 0 | R29: NWPacificSea | S29: Antilles | W29: ruthenian
A30: 28 | B30: America | C30: Central America | D30: Sonora | E30: plains | F30: pagan | G30: temperate | H30: aztec | I30: sugar | J30: Tampico | K30: 6 | L30: 3 | M30: 2 | N30: 0 | R30: AlaskaSea | S30: Guiana | W30: baltic
A31: 29 | B31: America | C31: Central America | D31: Azteca | E31: plains | F31: pagan | G31: tropical | H31: zapotec | I31: grain | J31: Tlaxcala | K31: 4 | L31: 5 | M31: 2 | N31: 0 | R31: HudsonBaySea | S31: Orenoque | W31: polish
A32: 30 | B32: America | C32: Central America | D32: Azteca | E32: plains | F32: pagan | G32: tropical | H32: zapotec | I32: fish | J32: Atlixco | K32: 4 | L32: 5 | M32: 1 | N32: 0 | R32: ArcticSeaSea | S32: Ecuador | W32: tatar
A33: 31 | B33: America | C33: Central America | D33: Azteca | E33: mountain | F33: pagan | G33: tropical | H33: zapotec | I33: chinaware | J33: Tehuantepec | K33: 3 | L33: 3 | M33: 1 | N33: 0 | R33: KamtchatkaSea | S33: Inca | W33: german
A34: 32 | B34: America | C34: Central America | D34: Azteca | E34: marsh | F34: pagan | G34: tropical | H34: mayan | I34: wool | J34: Tehuacan | K34: 5 | L34: 5 | M34: 1 | N34: 0 | R34: ENACoastSea | S34: Chili | W34: czech
A35: 33 | B35: America | C35: Central America | D35: Costa Rica | E35: mountain | F35: pagan | G35: tropical | H35: mayan | I35: chinaware | J35: Guatemala | K35: 4 | L35: 3 | M35: 1 | N35: 0 | R35: NAtlanticSea | S35: Amazonia | W35: slovak
... A63: 61 | B63: America | C63: North America | D63: Appalachia | E63: mountain | F63: pagan | G63: ncontinental | H63: cherokee | I63: fur | J63: Alleghany | K63: 6 | L63: 3 | M63: 1 | N63: 0 | R63: Lake | S63: Lotharingia | W63: hindi
A64: 62 | B64: America | C64: North America | D64: Appalachia | E64: forest | F64: pagan | G64: temperate | H64: creek | I64: cotton | J64: Carolina | K64: 5 | L64: 5 | M64: 2 | N64: 0 | S64: France | W64: marathi
A65: 63 | B65: America | C65: North America | D65: Appalachia | E65: forest | F65: pagan | G65: temperate | H65: creek | I65: cotton | J65: Santee | K65: 5 | L65: 4 | M65: 2 | N65: 0 | S65: Switzerland | W65: bengali
A66: 64 | B66: America | C66: North America | D66: Appalachia | E66: marsh | F66: pagan | G66: temperate | H66: creek | I66: tobacco | J66: Roanoke | K66: 6 | L66: 6 | M66: 2 | N66: 0 | S66: Iberia | W66: telugu
A67: 65 | B67: America | C67: North America | D67: Appalachia | E67: forest | F67: pagan | G67: ncontinental | H67: cherokee | I67: tobacco | J67: Catawba | K67: 5 | L67: 4 | M67: 1 | N67: 0 | S67: Steppe | W67: kannada
...
